Workbook

Sheet yields
A1: 0 | B1: 42064 | C1: 42078 | D1: 42156 | E1: 42248 | F1: 42262 | G1: 42339 | H1: 42339 | I1: 42430 | J1: 42444 | K1: 42522 | L1: 42614 | M1: 42614 | N1: 42628 | O1: 42705 | P1: 42809 | Q1: 42887 | R1: 42993 | S1: 43070 | T1: 43174 | U1: 43252 | V1: 43358 | W1: 43435 | X1: 43539 | Y1: 43617 | Z1: 43723 | AA1: 43800 | AB1: 43905 | AC1: 43983 | AD1: 43983 | AE1: 44089 | AF1: 44166 | AG1: 44270 | AH1: 44270 | AI1: 44348 | AJ1: 44348 | AK1: 44531 | AL1: 44713 | AM1: 44713 | AN1: 44896 | AO1: 45078 | AP1: 45078 | AQ1: 45261 | AR1: 45444 | AS1: 45627 | AT1: 45809 | AU1: 45809 | AV1: 47453 | AW1: 47635 | AX1: 47818 | AY1: 48000 | AZ1: 48183 | BA1: 48366 | BB1: 48549 | BC1: 48731 | BD1: 48731 | BE1: 51836 | BF1: 52018 | BG1: 52201 | BH1: 52383 | BI1: 52566 | BJ1: 52749 | BK1: 52932 | BL1: 53114 | BM1: 53297 | BN1: 53297 | BO1: 53479 | BP1: 53662 | BQ1: 53844 | BR1: 54027 | BS1: 54210 | BT1: 54393 | BU1: 54393 | BV1: 54575 | BW1: 54758 | BX1: 54940 | BY1: 55123 | BZ1: 55305 | CA1: 55488 | CB1: 55671 | CC1: 55854 | CD1: 56036 | CE1: 56219 | CF1: 56401 | CG1: 56584 | CH1: 56766 | CI1: 56949 | CJ1: 57132 | CK1: 57315 | CL1: 57497 | CM1: 57680 | CN1: 57862 | CO1: 58045 | CP1: 58227 | CQ1: 58410 | CR1: 58593 | CS1: 58776 | CT1: 58958 | CU1: 59141 | CV1: 59323 | CW1: 59506 | CX1: 59688 | CY1: 59871 | CZ1: 60054 | DA1: 60237 | DB1: 60237
A2: 42006 | B2: 0.88329 | C2: 0.97628 | D2: 0.94752 | E2: 0.95279 | F2: 0.97214 | G2: 1.02206 | H2: 1.03671 | I2: 0.96034 | J2: 0.99392 | K2: 1.01631 | L2: 1.01343 | M2: 0.99933 | N2: 1.10608 | O2: 1.11466 | P2: 1.04766 | Q2: 1.0728 | R2: 1.15012 | S2: 1.19306 | T2: 1.2104 | U2: 1.2312 | V2: 1.28181 | W2: 1.34603 | X2: 1.39843 | Y2: 1.34612 | Z2: 1.41706 | AA2: 1.41125 | AB2: 1.45638 | AC2: 1.41446 | AD2: 1.36108 | AE2: 1.51236 | AF2: 1.54594 | AG2: 1.60034 | AH2: 1.5843 | AI2: 1.61886 | AJ2: 1.45353 | AK2: 1.67725 | AL2: 1.73723 | AM2: 1.5939 | AN2: 1.79204 | AO2: 1.83093 | AP2: 1.65731 | AQ2: 1.88245 | AR2: 1.92497 | AS2: 1.95502 | AT2: 1.97108 | AU2: 1.88951 | AV2: 2.24468 | AW2: 2.24459 | AX2: 2.28349 | AY2: 2.30524 | AZ2: 2.32965 | BA2: 2.36229 | BB2: 2.38392 | BC2: 2.39882 | BD2: 2.28741 | BE2: 2.43362 | BF2: 2.42366 | BG2: 2.41349 | BH2: 2.40765 | BI2: 2.40767 | BJ2: 2.40502 | BK2: 2.40005 | BL2: 2.39435 | BM2: 2.39465 | BN2: 2.32379 | BO2: 2.38969 | BP2: 2.3897 | BQ2: 2.38146 | BR2: 2.38148 | BS2: 2.38149 | BV2: 2.3782 | BW2: 2.37755 | BX2: 2.37756 | BY2: 2.37491 | BZ2: 2.37493 | CA2: 2.37494 | CB2: 2.37495 | CC2: 2.37496 | CD2: 2.37164 | CE2: 2.37165 | CF2: 2.37166 | CG2: 2.37167 | CH2: 2.36535 | CI2: 2.36503 | CJ2: 2.36537 | CK2: 2.36538 | CL2: 2.36539 | CM2: 2.3654 | CN2: 2.36499 | CO2: 2.36292 | CP2: 2.35485 | CR2: 2.35793 | CS2: 2.34737 | CT2: 2.34738 | CU2: 2.34738 | CV2: 2.35545 | CW2: 2.35546 | CX2: 2.35295 | CY2: 2.36316 | CZ2: 2.34797 | DA2: 2.34797 | DB2: 2.25287
A3: 42009 | B3: 0.90966 | C3: 1.00072 | D3: 0.9568 | E3: 0.96171 | F3: 0.99748 | G3: 1.02519 | H3: 0.98308 | I3: 0.95205 | J3: 0.97027 | K3: 1.00383 | L3: 1.0039 | M3: 0.9847 | N3: 1.09589 | O3: 1.10389 | P3: 1.03673 | Q3: 1.05327 | R3: 1.10175 | S3: 1.1564 | T3: 1.18865 | U3: 1.20498 | V3: 1.25825 | W3: 1.32149 | X3: 1.36238 | Y3: 1.3098 | Z3: 1.38042 | AA3: 1.37511 | AB3: 1.42586 | AC3: 1.38373 | AD3: 1.31558 | AE3: 1.46859 | AF3: 1.49935 | AG3: 1.568 | AH3: 1.54976 | AI3: 1.57112 | AJ3: 1.40588 | AK3: 1.63129 | AL3: 1.68126 | AM3: 1.54399 | AN3: 1.74112 | AO3: 1.77822 | AP3: 1.60546 | AQ3: 1.83002 | AR3: 1.87181 | AS3: 1.90444 | AT3: 1.91795 | AU3: 1.83638 | AV3: 2.19166 | AW3: 2.20079 | AX3: 2.23061 | AY3: 2.25212 | AZ3: 2.27548 | BA3: 2.3072 | BB3: 2.3288 | BC3: 2.34394 | BD3: 2.22852 | BE3: 2.38059 | BF3: 2.37061 | BG3: 2.36078 | BH3: 2.35564 | BI3: 2.35565 | BJ3: 2.35282 | BK3: 2.34784 | BL3: 2.34234 | BM3: 2.34335 | BN3: 2.27339 | BO3: 2.33838 | BP3: 2.33839 | BQ3: 2.33005 | BR3: 2.33006 | BS3: 2.33007 | BV3: 2.32677 | BW3: 2.32578 | BX3: 2.32578 | BY3: 2.32346 | BZ3: 2.32347 | CA3: 2.32348 | CB3: 2.32348 | CC3: 2.32349 | CD3: 2.32016 | CE3: 2.32017 | CF3: 2.32017 | CG3: 2.32018 | CH3: 2.31352 | CI3: 2.31353 | CJ3: 2.31353 | CK3: 2.31354 | CL3: 2.31355 | CM3: 2.31355 | CN3: 2.31356 | CO3: 2.31106 | CP3: 2.30357 | CR3: 2.30606 | CS3: 2.29608 | CT3: 2.29609 | CU3: 2.29609 | CV3: 2.31559 | CW3: 2.3156 | CX3: 2.30107 | CY3: 2.29809 | CZ3: 2.29558 | DA3: 2.29558 | DB3: 2.20096
A4: 42010 | B4: 0.90375 | C4: 0.96936 | D4: 0.94822 | E4: 0.96166 | F4: 0.98319 | G4: 1.00845 | H4: 0.95354 | I4: 0.93615 | J4: 0.96694 | K4: 0.98725 | L4: 0.98797 | M4: 0.95978 | N4: 1.07872 | O4: 1.08645 | P4: 1.00981 | Q4: 1.02003 | R4: 1.09487 | S4: 1.13826 | T4: 1.14955 | U4: 1.16931 | V4: 1.23528 | W4: 1.28551 | X4: 1.31747 | Y4: 1.26271 | Z4: 1.3343 | AA4: 1.32752 | AB4: 1.36172 | AC4: 1.33542 | AD4: 1.26591 | AE4: 1.41732 | AF4: 1.44787 | AG4: 1.5002 | AH4: 1.48873 | AI4: 1.51469 | AJ4: 1.35485 | AK4: 1.57802 | AL4: 1.63524 | AM4: 1.48399 | AN4: 1.69411 | AO4: 1.72942 | AP4: 1.55628 | AQ4: 1.78159 | AR4: 1.82147 | AS4: 1.85357 | AT4: 1.86893 | AU4: 1.79433 | AV4: 2.14564 | AW4: 2.1435 | AX4: 2.1877 | AY4: 2.21095 | AZ4: 2.22842 | BA4: 2.25674 | BB4: 2.28248 | BC4: 2.29598 | BD4: 2.18672 | BE4: 2.33688 | BF4: 2.32691 | BG4: 2.31224 | BH4: 2.31197 | BI4: 2.31198 | BJ4: 2.30982 | BK4: 2.30484 | BL4: 2.29931 | BM4: 2.29933 | BN4: 2.23215 | BO4: 2.29436 | BP4: 2.29437 | BQ4: 2.28705 | BR4: 2.28706 | BS4: 2.28706 | BV4: 2.28376 | BW4: 2.28673 | BX4: 2.28674 | BY4: 2.28045 | BZ4: 2.28046 | CA4: 2.28047 | CB4: 2.2791 | CC4: 2.2791 | CD4: 2.27244 | CE4: 2.27245 | CF4: 2.27245 | CG4: 2.27717 | CH4: 2.27102 | CI4: 2.27052 | CJ4: 2.26951 | CK4: 2.26952 | CL4: 2.26952 | CM4: 2.26953 | CN4: 2.26953 | CO4: 2.26855 | CP4: 2.26106 | CR4: 2.26356 | CS4: 2.25357 | CT4: 2.25358 | CU4: 2.25358 | CV4: 2.26107 | CW4: 2.26107 | CX4: 2.25857 | CY4: 2.26753 | CZ4: 2.25402 | DA4: 2.25403 | DB4: 2.15859
A5: 42011 | B5: 0.87964 | C5: 0.97569 | D5: 0.94198 | E5: 0.95335 | F5: 0.97621 | G5: 0.9966 | H5: 0.95423 | I5: 0.94044 | J5: 0.96988 | K5: 0.99236 | L5: 0.99353 | M5: 0.96825 | N5: 1.08279 | O5: 1.0913 | P5: 1.01994 | Q5: 1.03015 | R5: 1.105 | S5: 1.14854 | T5: 1.15497 | U5: 1.17542 | V5: 1.24184 | W5: 1.29222 | X5: 1.32252 | Y5: 1.26982 | Z5: 1.34118 | AA5: 1.3353 | AB5: 1.38297 | AC5: 1.34045 | AD5: 1.27619 | AE5: 1.42488 | AF5: 1.45439 | AG5: 1.50549 | AH5: 1.49401 | AI5: 1.52624 | AJ5: 1.3622 | AK5: 1.58591 | AL5: 1.63585 | AM5: 1.48891 | AN5: 1.69847 | AO5: 1.73427 | AP5: 1.57078 | AQ5: 1.78667 | AR5: 1.82944 | AS5: 1.85776 | AT5: 1.87277 | AU5: 1.7982 | AV5: 2.15157 | AW5: 2.14933 | AX5: 2.1905 | AY5: 2.21116 | AZ5: 2.23569 | BA5: 2.26517 | BB5: 2.29093 | BC5: 2.30624 | BD5: 2.19573 | BE5: 2.33689 | BF5: 2.33294 | BG5: 2.32339 | BH5: 2.32229 | BI5: 2.32231 | BJ5: 2.31298 | BK5: 2.31351 | BL5: 2.31309 | BM5: 2.31643 | BN5: 2.24109 | BO5: 2.30612 | BP5: 2.30613 | BQ5: 2.29709 | BR5: 2.29711 | BS5: 2.29712 | BV5: 2.29383 | BW5: 2.29472 | BX5: 2.29474 | BY5: 2.29054 | BZ5: 2.29055 | CA5: 2.29056 | CB5: 2.28974 | CC5: 2.28975 | CD5: 2.28476 | CE5: 2.28477 | CF5: 2.28478 | CG5: 2.28729 | CH5: 2.27981 | CI5: 2.28065 | CJ5: 2.27983 | CK5: 2.27984 | CL5: 2.27985 | CM5: 2.27985 | CN5: 2.28141 | CO5: 2.27333 | CP5: 2.27084 | CR5: 2.26335 | CS5: 2.26336 | CT5: 2.26337 | CU5: 2.26338 | CV5: 2.28251 | CW5: 2.28252 | CX5: 2.2534 | CY5: 2.26043 | CZ5: 2.26192 | DA5: 2.26192 | DB5: 2.16815
A6: 42012 | B6: 0.86711 | C6: 0.94053 | D6: 0.93983 | E6: 0.95326 | F6: 0.97337 | G6: 1.00518 | H6: 0.95453 | I6: 0.94437 | J6: 0.97426 | K6: 0.99784 | L6: 0.99748 | M6: 0.97614 | N6: 1.0867 | O6: 1.09598 | P6: 1.01317 | Q6: 1.04267 | R6: 1.11826 | S6: 1.16177 | T6: 1.18632 | U6: 1.20221 | V6: 1.26893 | W6: 1.32077 | X6: 1.36192 | Y6: 1.31007 | Z6: 1.38019 | AA6: 1.37573 | AB6: 1.412 | AC6: 1.38308 | AD6: 1.31375 | AE6: 1.46678 | AF6: 1.49671 | AG6: 1.54779 | AH6: 1.53863 | AI6: 1.56521 | AJ6: 1.40405 | AK6: 1.6301 | AL6: 1.69037 | AM6: 1.54125 | AN6: 1.75304 | AO6: 1.79204 | AP6: 1.61462 | AQ6: 1.84835 | AR6: 1.88772 | AS6: 1.91589 | AT6: 1.93138 | AU6: 1.8515 | AV6: 2.21173 | AW6: 2.21053 | AX6: 2.25383 | AY6: 2.27514 | AZ6: 2.29419 | BA6: 2.32029 | BB6: 2.34605 | BC6: 2.3597 | BD6: 2.24129 | BE6: 2.40354 | BF6: 2.39358 | BG6: 2.38381 | BH6: 2.38668 | BI6: 2.3867 | BJ6: 2.38171 | BK6: 2.37674 | BL6: 2.37337 | BM6: 2.3696 | BN6: 2.29813 | BO6: 2.36463 | BP6: 2.36465 | BQ6: 2.35577 | BR6: 2.35578 | BS6: 2.35579 | BV6: 2.3525 | BW6: 2.35152 | BX6: 2.35153 | BY6: 2.34921 | BZ6: 2.34923 | CA6: 2.34924 | CB6: 2.34925 | CC6: 2.34926 | CD6: 2.34594 | CE6: 2.34595 | CF6: 2.34596 | CG6: 2.34597 | CH6: 2.33904 | CI6: 2.33933 | CJ6: 2.3399 | CK6: 2.33991 | CL6: 2.33992 | CM6: 2.33993 | CN6: 2.33994 | CO6: 2.3316 | CP6: 2.32911 | CR6: 2.33161 | CS6: 2.32164 | CT6: 2.32165 | CU6: 2.32165 | CV6: 2.342 | CW6: 2.32914 | CX6: 2.32663 | CY6: 2.31169 | CZ6: 2.32115 | DA6: 2.32116 | DB6: 2.22683
A7: 42013 | B7: 0.86655 | C7: 0.93518 | D7: 0.93312 | E7: 0.95317 | F7: 0.97311 | G7: 0.99936 | H7: 1.02572 | I7: 0.92853 | J7: 0.95752 | K7: 0.9801 | L7: 0.9816 | M7: 0.9483 | N7: 1.07092 | O7: 1.0808 | P7: 0.9828 | Q7: 1.01234 | R7: 1.08797 | S7: 1.13109 | T7: 1.14555 | U7: 1.16096 | V7: 1.23016 | W7: 1.27393 | X7: 1.3181 | Y7: 1.26569 | Z7: 1.33674 | AA7: 1.33069 | AB7: 1.36706 | AC7: 1.3378 | AD7: 1.26939 | AE7: 1.42187 | AF7: 1.45218 | AG7: 1.50327 | AH7: 1.49412 | AI7: 1.51867 | AJ7: 1.35907 | AK7: 1.58303 | AL7: 1.64583 | AM7: 1.49825 | AN7: 1.70781 | AO7: 1.7483 | AP7: 1.57568 | AQ7: 1.80051 | AR7: 1.84239 | AS7: 1.87266 | AT7: 1.88586 | AU7: 1.80737 | AV7: 2.16988 | AW7: 2.16825 | AX7: 2.21197 | AY7: 2.23292 | AZ7: 2.25179 | BA7: 2.27628 | BB7: 2.30204 | BC7: 2.31708 | BD7: 2.20096 | BE7: 2.35866 | BF7: 2.3487 | BG7: 2.34338 | BH7: 2.34302 | BI7: 2.34304 | BJ7: 2.34277 | BK7: 2.33613 | BL7: 2.32948 | BM7: 2.32049 | BN7: 2.25587 | BO7: 2.3203 | BP7: 2.32032 | BQ7: 2.31188 | BR7: 2.3119 | BS7: 2.31191 | BV7: 2.30862 | BW7: 2.30763 | BX7: 2.30765 | BY7: 2.30533 | BZ7: 2.30534 | CA7: 2.30535 | CB7: 2.30536 | CC7: 2.30538 | CD7: 2.30205 | CE7: 2.30206 | CF7: 2.30207 | CG7: 2.30208 | CH7: 2.29538 | CI7: 2.29544 | CJ7: 2.29556 | CK7: 2.29557 | CL7: 2.29558 | CM7: 2.29559 | CN7: 2.2956 | CO7: 2.28794 | CP7: 2.28545 | CR7: 2.28795 | CS7: 2.27798 | CT7: 2.27798 | CU7: 2.27799 | CV7: 2.29766 | CW7: 2.29766 | CX7: 2.28297 | CY7: 2.28 | CZ7: 2.27749 | DA7: 2.2775 | DB7: 2.18294
A8: 42016 | B8: 0.90554 | C8: 0.97282 | D8: 0.95367 | E8: 0.96529 | F8: 0.9818 | G8: 1.0085 | H8: 0.96233 | I8: 0.92513 | J8: 0.95218 | K8: 0.97707 | L8: 0.97698 | M8: 0.93201 | N8: 1.06246 | O8: 1.07295 | P8: 0.95454 | Q8: 0.98369 | R8: 1.05873 | S8: 1.10206 | T8: 1.10873 | U8: 1.12583 | V8: 1.1939 | W8: 1.24395 | X8: 1.27737 | Y8: 1.22369 | Z8: 1.29466 | AA8: 1.28943 | AB8: 1.32402 | AC8: 1.2959 | AD8: 1.23099 | AE8: 1.37994 | AF8: 1.41044 | AG8: 1.46179 | AH8: 1.45287 | AI8: 1.47709 | AJ8: 1.32912 | AK8: 1.5413 | AL8: 1.5977 | AM8: 1.44832 | AN8: 1.65755 | AO8: 1.69848 | AP8: 1.5221 | AQ8: 1.75493 | AR8: 1.79589 | AS8: 1.82386 | AT8: 1.83606 | AU8: 1.75677 | AV8: 2.12103 | AW8: 2.11887 | AX8: 2.15987 | AY8: 2.1802 | AZ8: 2.20239 | BA8: 2.22689 | BB8: 2.25263 | BC8: 2.26569 | BD8: 2.15072 | BE8: 2.30789 | BF8: 2.29792 | BG8: 2.29322 | BH8: 2.29229 | BI8: 2.2923 | BJ8: 2.28731 | BK8: 2.28232 | BL8: 2.27583 | BM8: 2.27524 | BN8: 2.20532 | BO8: 2.27026 | BP8: 2.27027 | BQ8: 2.26198 | BR8: 2.26199 | BS8: 2.262 | BV8: 2.25869 | BW8: 2.2577 | BX8: 2.25771 | BY8: 2.25539 | BZ8: 2.25539 | CA8: 2.2554 | CB8: 2.25541 | CC8: 2.25541 | CD8: 2.25208 | CE8: 2.25209 | CF8: 2.25209 | CG8: 2.2521 | CH8: 2.245 | CI8: 2.24545 | CJ8: 2.24595 | CK8: 2.24596 | CL8: 2.24596 | CM8: 2.24597 | CN8: 2.24543 | CO8: 2.24253 | CP8: 2.23599 | CR8: 2.2285 | CS8: 2.2285 | CT8: 2.2285 | CU8: 2.22851 | CV8: 2.24652 | CW8: 2.24653 | CX8: 2.23254 | CY8: 2.22518 | CZ8: 2.22705 | DA8: 2.22706 | DB8: 2.13289
A9: 42017 | B9: 0.90396 | C9: 0.9716 | D9: 0.95433 | E9: 0.96523 | F9: 0.98474 | G9: 0.99995 | H9: 0.94597 | I9: 0.92313 | J9: 0.95162 | K9: 0.97152 | L9: 0.97498 | M9: 0.92819 | N9: 1.06476 | O9: 1.05373 | P9: 0.95657 | Q9: 0.97858 | R9: 1.05414 | S9: 1.08195 | T9: 1.10042 | U9: 1.12017 | V9: 1.18589 | W9: 1.23648 | X9: 1.25837 | Y9: 1.20434 | Z9: 1.27607 | AA9: 1.26955 | AB9: 1.30511 | AC9: 1.27683 | AD9: 1.21083 | AE9: 1.36103 | AF9: 1.39167 | AG9: 1.44345 | AH9: 1.43542 | AI9: 1.45761 | AJ9: 1.29714 | AK9: 1.52138 | AL9: 1.58453 | AM9: 1.43495 | AN9: 1.64438 | AO9: 1.68632 | AP9: 1.51785 | AQ9: 1.73886 | AR9: 1.78411 | AS9: 1.81362 | AT9: 1.82269 | AU9: 1.74196 | AV9: 2.10941 | AW9: 2.10837 | AX9: 2.14928 | AY9: 2.16808 | AZ9: 2.1875 | BA9: 2.21898 | BB9: 2.24227 | BC9: 2.25909 | BD9: 2.14308 | BE9: 2.29305 | BF9: 2.28799 | BG9: 2.27843 | BH9: 2.27698 | BI9: 2.28061 | BJ9: 2.27562 | BK9: 2.27063 | BL9: 2.26839 | BM9: 2.26385 | BN9: 2.19306 | BO9: 2.25887 | BP9: 2.25888 | BQ9: 2.25039 | BR9: 2.2504 | BS9: 2.25041 | BV9: 2.2471 | BW9: 2.24883 | BX9: 2.24884 | BY9: 2.2438 | BZ9: 2.2438 | CA9: 2.24381 | CB9: 2.24377 | CC9: 2.24377 | CD9: 2.23888 | CE9: 2.23889 | CF9: 2.23889 | CG9: 2.24051 | CH9: 2.23331 | CI9: 2.23386 | CJ9: 2.23332 | CK9: 2.23332 | CL9: 2.23333 | CM9: 2.23333 | CN9: 2.23405 | CO9: 2.22679 | CP9: 2.22429 | CR9: 2.2168 | CS9: 2.21681 | CT9: 2.21681 | CU9: 2.21681 | CV9: 2.22335 | CW9: 2.22336 | CX9: 2.22085 | CY9: 2.21896 | CZ9: 2.21635 | DA9: 2.21636 | DB9: 2.12196
A10: 42018 | B10: 0.88203 | C10: 0.9674 | D10: 0.93696 | E10: 0.95663 | F10: 0.97407 | G10: 0.98741 | H10: 0.9184 | I10: 0.89975 | J10: 0.93161 | K10: 0.94765 | L10: 0.95278 | M10: 0.90155 | N10: 1.04546 | O10: 1.03075 | P10: 0.91545 | Q10: 0.94779 | R10: 1.01884 | S10: 1.0476 | T10: 1.06772 | U10: 1.08948 | V10: 1.15657 | W10: 1.20731 | X10: 1.24514 | Y10: 1.16722 | Z10: 1.24063 | AA10: 1.23021 | AB10: 1.26707 | AC10: 1.234 | AD10: 1.17362 | AE10: 1.31602 | AF10: 1.34432 | AG10: 1.41327 | AH10: 1.39512 | AI10: 1.41676 | AJ10: 1.25452 | AK10: 1.48062 | AL10: 1.54947 | AM10: 1.39799 | AN10: 1.60935 | AO10: 1.65096 | AP10: 1.48029 | AQ10: 1.70715 | AR10: 1.74705 | AS10: 1.7766 | AT10: 1.77978 | AU10: 1.69643 | AV10: 2.07868 | AW10: 2.08224 | AX10: 2.11469 | AY10: 2.13622 | AZ10: 2.15722 | BA10: 2.18672 | BB10: 2.21109 | BC10: 2.22304 | BD10: 2.10607 | BE10: 2.25862 | BF10: 2.25353 | BG10: 2.24354 | BH10: 2.24619 | BI10: 2.24621 | BJ10: 2.24122 | BK10: 2.23625 | BL10: 2.23397 | BM10: 2.22407 | BN10: 2.15878 | BO10: 2.22414 | BP10: 2.22416 | BQ10: 2.21612 | BR10: 2.21614 | BS10: 2.21615 | BV10: 2.21286 | BW10: 2.21454 | BX10: 2.21455 | BY10: 2.20957 | BZ10: 2.20958 | CA10: 2.20959 | CB10: 2.20989 | CC10: 2.2099 | CD10: 2.20462 | CE10: 2.20463 | CF10: 2.20464 | CG10: 2.20631 | CH10: 2.19953 | CI10: 2.19967 | CJ10: 2.20011 | CK10: 2.20012 | CL10: 2.20013 | CM10: 2.20013 | CN10: 2.19943 | CO10: 2.19709 | CP10: 2.19016 | CR10: 2.1921 | CS10: 2.18268 | CT10: 2.18269 | CU10: 2.1827 | CV10: 2.18962 | CW10: 2.18963 | CX10: 2.18712 | CY10: 2.18969 | CZ10: 2.18257 | DA10: 2.18257 | DB10: 2.08779
A11: 42019 | B11: 0.84704 | C11: 0.90747 | D11: 0.90214 | E11: 0.95654 | F11: 0.94818 | G11: 0.95399 | H11: 0.99899 | I11: 0.85231 | J11: 0.88812 | K11: 0.89688 | L11: 0.90518 | M11: 0.84206 | N11: 0.96444 | O11: 0.97841 | P11: 0.84634 | Q11: 0.87271 | R11: 0.94762 | S11: 0.99316 | T11: 0.98055 | U11: 1.0131 | V11: 1.07809 | W11: 1.11631 | X11: 1.1236 | Y11: 1.09964 | Z11: 1.15557 | AA11: 1.14204 | AB11: 1.20112 | AC11: 1.16907 | AD11: 1.07678 | AE11: 1.24644 | AF11: 1.25807 | AG11: 1.36211 | AH11: 1.30784 | AI11: 1.34018 | AJ11: 1.1579 | AK11: 1.39826 | AL11: 1.47774 | AM11: 1.3003 | AN11: 1.53368 | AO11: 1.57275 | AP11: 1.396 | AQ11: 1.62083 | AR11: 1.65831 | AS11: 1.69039 | AT11: 1.68515 | AU11: 1.62009 | AV11: 1.98301 | AW11: 1.95856 | AX11: 2.02809 | AY11: 2.05156 | AZ11: 2.0732 | BA11: 2.10635 | BB11: 2.13917 | BC11: 2.14812 | BD11: 2.02891 | BE11: 2.18926 | BF11: 2.1793 | BG11: 2.16889 | BH11: 2.17221 | BI11: 2.17223 | BJ11: 2.16725 | BK11: 2.16227 | BL11: 2.15974 | BM11: 2.14911 | BN11: 2.08416 | BO11: 2.14868 | BP11: 2.1487 | BQ11: 2.14083 | BR11: 2.14084 | BS11: 2.14085 | BV11: 2.13756 | BW11: 2.14155 | BX11: 2.14156 | BY11: 2.13427 | BZ11: 2.13428 | CA11: 2.13429 | CB11: 2.13494 | CC11: 2.13495 | CD11: 2.12754 | CE11: 2.12755 | CF11: 2.12756 | CG11: 2.13101 | CH11: 2.12505 | CI11: 2.12437 | CJ11: 2.12506 | CK11: 2.12507 | CL11: 2.12508 | CM11: 2.12509 | CN11: 2.12396 | CO11: 2.1226 | CP11: 2.1142 | CR11: 2.11762 | CS11: 2.10672 | CT11: 2.11763 | CU11: 2.11764 | CV11: 2.11513 | CW11: 2.11514 | CX11: 2.11263 | CY11: 2.1225 | CZ11: 2.1077 | DA11: 2.1077 | DB11: 2.01223
A12: 42020 | B12: 0.85024 | C12: 0.92197 | D12: 0.926 | E12: 0.95644 | F12: 0.96043 | G12: 0.97832 | H12: 1.04739 | I12: 0.89377 | J12: 0.91642 | K12: 0.94296 | L12: 0.9468 | M12: 0.89281 | N12: 1.02905 | O12: 1.03791 | P12: 0.89266 | Q12: 0.92387 | R12: 1.00492 | S12: 1.04056 | T12: 1.04209 | U12: 1.05091 | V12: 1.12743 | W12: 1.15287 | X12: 1.21026 | Y12: 1.13578 | Z12: 1.19817 | AA12: 1.19892 | AB12: 1.22634 | AC12: 1.2092 | AD12: 1.14644 | AE12: 1.27417 | AF12: 1.3036 | AG12: 1.37523 | AH12: 1.37231 | AI12: 1.38794 | AJ12: 1.22847 | AK12: 1.43989 | AL12: 1.50695 | AM12: 1.36339 | AN12: 1.57122 | AO12: 1.61369 | AP12: 1.43545 | AQ12: 1.66589 | AR12: 1.70368 | AS12: 1.73885 | AT12: 1.72031 | AU12: 1.66795 | AV12: 2.03253 | AW12: 2.01455 | AX12: 2.07719 | AY12: 2.10858 | AZ12: 2.12518 | BA12: 2.1522 | BB12: 2.17455 | BC12: 2.18692 | BD12: 2.06896 | BE12: 2.22433 | BF12: 2.22038 | BG12: 2.21073 | BH12: 2.20884 | BI12: 2.21242 | BJ12: 2.20743 | BK12: 2.20246 | BL12: 2.20083 | BM12: 2.19589 | BN12: 2.12531 | BO12: 2.19092 | BP12: 2.19094 | BQ12: 2.18265 | BR12: 2.18266 | BS12: 2.18268 | BV12: 2.17938 | BW12: 2.17939 | BX12: 2.1794 | BY12: 2.17609 | BZ12: 2.1761 | CA12: 2.17611 | CB12: 2.1766 | CC12: 2.17661 | CD12: 2.17367 | CE12: 2.17368 | CF12: 2.17369 | CG12: 2.17283 | CH12: 2.16574 | CI12: 2.16619 | CJ12: 2.16668 | CK12: 2.16669 | CL12: 2.1667 | CM12: 2.16671 | CN12: 2.1662 | CO12: 2.1633 | CP12: 2.15674 | CR12: 2.14925 | CS12: 2.14926 | CT12: 2.14927 | CU12: 2.14927 | CV12: 2.16813 | CW12: 2.15584 | CX12: 2.15333 | CY12: 2.15115 | CZ12: 2.14864 | DA12: 2.14864 | DB12: 2.05655
A13: 42023 | B13: 0.89346 | C13: 0.9546 | D13: 0.93067 | E13: 0.96588 | F13: 0.97017 | G13: 0.98215 | H13: 0.98352 | I13: 0.89523 | J13: 0.92251 | K13: 0.93656 | L13: 0.94707 | M13: 0.88535 | N13: 1.03552 | O13: 1.02012 | P13: 0.89854 | Q13: 0.92054 | R13: 1.02095 | S13: 1.03259 | T13: 1.02575 | U13: 1.04418 | V13: 1.1111 | W13: 1.16167 | X13: 1.17698 | Y13: 1.12365 | Z13: 1.19389 | AA13: 1.19023 | AB13: 1.24083 | AC13: 1.19986 | AD13: 1.13405 | AE13: 1.28298 | AF13: 1.31385 | AG13: 1.35714 | AH13: 1.3454 | AI13: 1.3779 | AJ13: 1.23736 | AK13: 1.43707 | AL13: 1.49338 | AM13: 1.33972 | AN13: 1.55322 | AO13: 1.59506 | AP13: 1.42281 | AQ13: 1.64743 | AR13: 1.68853 | AS13: 1.71812 | AT13: 1.73209 | AU13: 1.6554 | AV13: 2.02638 | AW13: 2.02235 | AX13: 2.06219 | AY13: 2.08633 | AZ13: 2.10265 | BA13: 2.1297 | BB13: 2.15544 | BC13: 2.17035 | BD13: 2.0479 | BE13: 2.20603 | BF13: 2.20095 | BG13: 2.19143 | BH13: 2.19034 | BI13: 2.19408 | BJ13: 2.18909 | BK13: 2.18411 | BL13: 2.18135 | BM13: 2.17738 | BN13: 2.10675 | BO13: 2.1724 | BP13: 2.17241 | BQ13: 2.16409 | BR13: 2.16409 | BS13: 2.1641 | BV13: 2.1608 | BW13: 2.16208 | BX13: 2.16209 | BY13: 2.15749 | BZ13: 2.1575 | CA13: 2.1575 | CB13: 2.15724 | CC13: 2.15724 | CD13: 2.15213 | CE13: 2.15213 | CF13: 2.15214 | CG13: 2.1542 | CH13: 2.14727 | CI13: 2.14755 | CJ13: 2.14784 | CK13: 2.14784 | CL13: 2.14785 | CM13: 2.14785 | CN13: 2.14757 | CO13: 2.14481 | CP13: 2.13787 | CR13: 2.13038 | CS13: 2.13038 | CT13: 2.13038 | CU13: 2.13039 | CV13: 2.14855 | CW13: 2.14856 | CX13: 2.14856 | CY13: 2.13133 | CZ13: 2.12883 | DA13: 2.12883 | DB13: 2.03698
... A41: 42062 | B41: 0.29449 | C41: 0.48069 | D41: 0.57015 | E41: 0.59736 | F41: 0.59478 | G41: 0.61229 | H41: 0.50376 | I41: 0.49805 | J41: 0.53885 | K41: 0.54552 | L41: 0.54991 | M41: 0.47929 | N41: 0.65386 | O41: 0.62252 | P41: 0.52414 | Q41: 0.53431 | R41: 0.58315 | S41: 0.64672 | T41: 0.60614 | U41: 0.59616 | V41: 0.66822 | W41: 0.71032 | X41: 0.7373 | Y41: 0.68465 | Z41: 0.7556 | AA41: 0.75562 | AB41: 0.8284 | AC41: 0.8008 | AD41: 0.74208 | AE41: 0.88748 | AF41: 0.92366 | AG41: 0.98204 | AH41: 0.94119 | AI41: 0.96892 | AJ41: 0.82141 | AK41: 1.05497 | AL41: 1.134 | AM41: 0.95335 | AN41: 1.17831 | AO41: 1.25333 | AP41: 1.08391 | AQ41: 1.30503 | AR41: 1.3602 | AS41: 1.39064 | AT41: 1.3896 | AU41: 1.32791 | AV41: 1.78286 | AW41: 1.79879 | AX41: 1.83031 | AY41: 1.84226 | AZ41: 1.85846 | BA41: 1.93018 | BB41: 1.9611 | BC41: 1.9991 | BD41: 1.89222 | BE41: 2.05596 | BF41: 2.05098 | BG41: 2.05042 | BH41: 2.04102 | BI41: 2.04104 | BJ41: 2.03605 | BK41: 2.03108 | BL41: 2.03083 | BM41: 2.00524 | BN41: 1.98322 | BO41: 2.0112 | BP41: 2.01122 | BQ41: 1.99878 | BR41: 1.99879 | BS41: 1.9988 | BV41: 2.00971 | BW41: 2.0133 | BX41: 2.0013 | BY41: 1.998 | BZ41: 1.99801 | CA41: 1.99802 | CB41: 1.99803 | CC41: 1.99804 | CD41: 1.99472 | CE41: 1.99473 | CF41: 1.99474 | CG41: 1.99395 | CH41: 1.99385 | CI41: 1.98618 | CJ41: 1.98397 | CK41: 1.98398 | CL41: 1.98399 | CM41: 1.984 | CN41: 1.9815 | CO41: 1.97651 | CP41: 1.98147 | CR41: 1.98237 | CS41: 1.98051 | CT41: 1.98051 | CU41: 1.98052 | CV41: 1.97304 | CW41: 1.97305 | CX41: 1.97054 | CY41: 1.96557 | CZ41: 1.96307 | DA41: 1.96307 | DB41: 1.876
A42: 42065 | C42: 0.55281 | D42: 0.57501 | E42: 0.60385 | F42: 0.60188 | G42: 0.61105 | H42: 0.52932 | I42: 0.52587 | J42: 0.55081 | K42: 0.56274 | L42: 0.5778 | M42: 0.5062 | N42: 0.66003 | O42: 0.63233 | P42: 0.54134 | Q42: 0.56498 | R42: 0.62979 | S42: 0.6705 | T42: 0.6297 | U42: 0.61947 | V42: 0.6933 | W42: 0.72734 | X42: 0.79797 | Y42: 0.7454 | Z42: 0.81589 | AA42: 0.81158 | AB42: 0.88869 | AC42: 0.89415 | AD42: 0.80328 | AE42: 0.94695 | AF42: 0.98935 | AG42: 1.04388 | AH42: 1.04105 | AI42: 1.03744 | AJ42: 0.89989 | AK42: 1.11182 | AL42: 1.21331 | AM42: 1.03311 | AN42: 1.26276 | AO42: 1.33962 | AP42: 1.16943 | AQ42: 1.39132 | AR42: 1.4444 | AS42: 1.47701 | AT42: 1.47466 | AU42: 1.40843 | AV42: 1.86137 | AW42: 1.87825 | AX42: 1.90541 | AY42: 1.92099 | AZ42: 1.93794 | BA42: 2.0105 | BB42: 2.03991 | BC42: 2.06645 | BD42: 1.96872 | BE42: 2.12157 | BF42: 2.11658 | BG42: 2.11656 | BH42: 2.10661 | BI42: 2.10662 | BJ42: 2.10162 | BK42: 2.09664 | BL42: 2.09164 | BM42: 2.07257 | BN42: 2.04935 | BO42: 2.07667 | BP42: 2.07668 | BQ42: 2.06559 | BR42: 2.0656 | BS42: 2.06561 | BV42: 2.07472 | BW42: 2.07473 | BX42: 2.06673 | BY42: 2.06342 | BZ42: 2.06343 | CA42: 2.06343 | CB42: 2.06344 | CC42: 2.06344 | CD42: 2.06012 | CE42: 2.06013 | CF42: 2.06013 | CG42: 2.06014 | CH42: 2.05919 | CI42: 2.05304 | CJ42: 2.05071 | CK42: 2.05072 | CL42: 2.05072 | CM42: 2.05073 | CN42: 2.04823 | CO42: 2.04324 | CP42: 2.04683 | CR42: 2.04732 | CS42: 2.05113 | CT42: 2.05113 | CU42: 2.05114 | CV42: 2.03969 | CW42: 2.03969 | CX42: 2.03718 | CY42: 2.02328 | CZ42: 2.02971 | DA42: 2.02971 | DB42: 1.93903
A43: 42066 | C43: 0.57749 | D43: 0.57672 | E43: 0.6038 | F43: 0.60701 | G43: 0.6157 | H43: 0.53384 | I43: 0.60819 | J43: 0.55236 | K43: 0.57262 | L43: 0.58178 | M43: 0.50697 | N43: 0.64584 | O43: 0.6316 | P43: 0.53509 | Q43: 0.56688 | R43: 0.60862 | S43: 0.67077 | T43: 0.6155 | U43: 0.60502 | V43: 0.6823 | W43: 0.72118 | X43: 0.83229 | Y43: 0.76385 | Z43: 0.83252 | AA43: 0.8326 | AB43: 0.92775 | AC43: 0.90381 | AD43: 0.82841 | AE43: 0.97579 | AF43: 1.0164 | AG43: 1.05997 | AH43: 1.06836 | AI43: 1.06981 | AJ43: 0.94343 | AK43: 1.14176 | AL43: 1.25971 | AM43: 1.07916 | AN43: 1.30709 | AO43: 1.38868 | AP43: 1.21948 | AQ43: 1.44038 | AR43: 1.48672 | AS43: 1.5263 | AT43: 1.52054 | AU43: 1.45268 | AV43: 1.90704 | AW43: 1.92336 | AX43: 1.95437 | AY43: 1.96606 | AZ43: 1.98299 | BA43: 2.0524 | BB43: 2.09134 | BC43: 2.11081 | BD43: 2.02204 | BE43: 2.17188 | BF43: 2.16689 | BG43: 2.16715 | BH43: 2.15592 | BI43: 2.15593 | BJ43: 2.16509 | BK43: 2.15086 | BL43: 2.1442 | BM43: 2.12986 | BN43: 2.09757 | BO43: 2.12489 | BP43: 2.1249 | BQ43: 2.12849 | BR43: 2.1285 | BS43: 2.12851 | BV43: 2.12354 | BW43: 2.12596 | BX43: 2.1189 | BY43: 2.11164 | BZ43: 2.11165 | CA43: 2.11165 | CB43: 2.11395 | CC43: 2.11395 | CD43: 2.10835 | CE43: 2.10835 | CF43: 2.10836 | CG43: 2.10836 | CH43: 2.10613 | CI43: 2.09877 | CJ43: 2.10171 | CK43: 2.10171 | CL43: 2.10172 | CM43: 2.10172 | CN43: 2.10379 | CO43: 2.10114 | CP43: 2.09345 | CR43: 2.09373 | CS43: 2.08027 | CT43: 2.08027 | CU43: 2.08028 | CV43: 2.08128 | CW43: 2.08128 | CX43: 2.07878 | CY43: 2.07379 | CZ43: 2.07129 | DA43: 2.0713 | DB43: 1.98914
A44: 42067 | C44: 0.55336 | D44: 0.62619 | E44: 0.64552 | F44: 0.68515 | G44: 0.66214 | H44: 0.61988 | I44: 0.67451 | J44: 0.64513 | K44: 0.66747 | L44: 0.69159 | M44: 0.62062 | N44: 0.74231 | O44: 0.73619 | P44: 0.6546 | Q44: 0.67944 | R44: 0.7432 | S44: 0.78315 | T44: 0.72082 | U44: 0.70674 | V44: 0.78333 | W44: 0.81272 | X44: 0.93371 | Y44: 0.86199 | Z44: 0.93558 | AA44: 0.93458 | AB44: 1.0287 | AC44: 0.99024 | AD44: 0.92995 | AE44: 1.07517 | AF44: 1.10696 | AG44: 1.15602 | AH44: 1.14577 | AI44: 1.1609 | AJ44: 1.04121 | AK44: 1.23524 | AL44: 1.34214 | AM44: 1.15985 | AN44: 1.39187 | AO44: 1.47643 | AP44: 1.30617 | AQ44: 1.52274 | AR44: 1.56898 | AS44: 1.60378 | AT44: 1.59934 | AU44: 1.53095 | AV44: 1.98332 | AW44: 1.99884 | AX44: 2.03095 | AY44: 2.04175 | AZ44: 2.06275 | BA44: 2.12086 | BB44: 2.15561 | BC44: 2.18031 | BD44: 2.09442 | BE44: 2.23642 | BF44: 2.23144 | BG44: 2.23104 | BH44: 2.22149 | BI44: 2.22151 | BJ44: 2.23067 | BK44: 2.21155 | BL44: 2.2098 | BM44: 2.20156 | BN44: 2.16215 | BO44: 2.18926 | BP44: 2.18927 | BQ44: 2.21077 | BR44: 2.21079 | BS44: 2.2108 | BV44: 2.18919 | BW44: 2.19161 | BX44: 2.18363 | BY44: 2.17606 | BZ44: 2.17608 | CA44: 2.17609 | CB44: 2.18167 | CC44: 2.18168 | CD44: 2.17503 | CE44: 2.17504 | CF44: 2.17505 | CG44: 2.17154 | CH44: 2.1682 | CI44: 2.16323 | CJ44: 2.16618 | CK44: 2.16158 | CL44: 2.16159 | CM44: 2.16937 | CN44: 2.16454 | CO44: 2.16688 | CP44: 2.15794 | CR44: 2.15946 | CS44: 2.14414 | CT44: 2.14415 | CU44: 2.14416 | CV44: 2.14702 | CW44: 2.14702 | CX44: 2.14453 | CY44: 2.13954 | CZ44: 2.13705 | DA44: 2.13705 | DB44: 2.05367
A45: 42068 | C45: 0.46842 | D45: 0.61746 | E45: 0.64542 | F45: 0.65136 | G45: 0.67426 | H45: 0.62076 | I45: 0.68435 | J45: 0.65644 | K45: 0.6786 | L45: 0.70346 | M45: 0.63242 | N45: 0.75337 | O45: 0.74686 | P45: 0.6686 | Q45: 0.69212 | R45: 0.7565 | S45: 0.79692 | T45: 0.7411 | U45: 0.72777 | V45: 0.80335 | W45: 0.84185 | X45: 0.95418 | Y45: 0.88048 | Z45: 0.95397 | AA45: 0.95299 | AB45: 1.02862 | AC45: 1.02123 | AD45: 0.94497 | AE45: 1.09158 | AF45: 1.11691 | AG45: 1.17707 | AH45: 1.1671 | AI45: 1.18231 | AJ45: 1.06222 | AK45: 1.25644 | AL45: 1.37086 | AM45: 1.19716 | AN45: 1.421 | AO45: 1.50038 | AP45: 1.33644 | AQ45: 1.54668 | AR45: 1.5875 | AS45: 1.62165 | AT45: 1.6155 | AU45: 1.54573 | AV45: 2.00802 | AW45: 2.02464 | AX45: 2.05234 | AY45: 2.06762 | AZ45: 2.08342 | BA45: 2.1477 | BB45: 2.19242 | BC45: 2.21076 | BD45: 2.11604 | BE45: 2.26248 | BF45: 2.2575 | BG45: 2.25736 | BH45: 2.24234 | BI45: 2.24657 | BJ45: 2.25666 | BK45: 2.23661 | BL45: 2.23579 | BM45: 2.22209 | BN45: 2.19071 | BO45: 2.21712 | BP45: 2.21714 | BQ45: 2.21381 | BR45: 2.21383 | BS45: 2.21384 | BV45: 2.21055 | BW45: 2.21426 | BX45: 2.21129 | BY45: 2.20393 | BZ45: 2.20394 | CA45: 2.20395 | CB45: 2.20635 | CC45: 2.20636 | CD45: 2.20065 | CE45: 2.20066 | CF45: 2.20067 | CG45: 2.19939 | CH45: 2.19698 | CI45: 2.19386 | CJ45: 2.19129 | CK45: 2.19129 | CL45: 2.1913 | CM45: 2.19407 | CN45: 2.19647 | CO45: 2.18908 | CP45: 2.19447 | CR45: 2.18692 | CS45: 2.1794 | CT45: 2.17941 | CU45: 2.17941 | CV45: 2.16639 | CW45: 2.16639 | CX45: 2.1639 | CY45: 2.16391 | CZ45: 2.16497 | DA45: 2.16498 | DB45: 2.08087
A46: 42069 | C46: 0.43822 | D46: 0.60936 | E46: 0.65503 | F46: 0.64952 | G46: 0.67746 | H46: 0.61276 | I46: 0.68925 | J46: 0.6603 | K46: 0.68252 | L46: 0.69057 | M46: 0.62865 | N46: 0.76774 | O46: 0.7589 | P46: 0.67874 | Q46: 0.68529 | R46: 0.73843 | S46: 0.80436 | T46: 0.75013 | U46: 0.73668 | V46: 0.81005 | W46: 0.85002 | X46: 0.98884 | Y46: 0.92229 | Z46: 0.99657 | AA46: 0.9943 | AB46: 1.07742 | AC46: 1.07173 | AD46: 0.99856 | AE46: 1.14155 | AF46: 1.17448 | AG46: 1.23132 | AH46: 1.22955 | AI46: 1.23883 | AJ46: 1.11731 | AK46: 1.31228 | AL46: 1.43369 | AM46: 1.25151 | AN46: 1.48895 | AO46: 1.5825 | AP46: 1.41688 | AQ46: 1.62881 | AR46: 1.67234 | AS46: 1.70587 | AT46: 1.70258 | AU46: 1.63982 | AV46: 2.0987 | AW46: 2.11519 | AX46: 2.14621 | AY46: 2.16401 | AZ46: 2.17901 | BA46: 2.23559 | BB46: 2.27045 | BC46: 2.30735 | BD46: 2.21831 | BE46: 2.36305 | BF46: 2.35807 | BG46: 2.35785 | BH46: 2.34284 | BI46: 2.34714 | BJ46: 2.35792 | BK46: 2.33718 | BL46: 2.33628 | BM46: 2.32259 | BN46: 2.29358 | BO46: 2.31762 | BP46: 2.31764 | BQ46: 2.31431 | BR46: 2.31433 | BS46: 2.31434 | BV46: 2.31105 | BW46: 2.31809 | BX46: 2.31659 | BY46: 2.30443 | BZ46: 2.30445 | CA46: 2.30446 | CB46: 2.30764 | CC46: 2.30765 | CD46: 2.30334 | CE46: 2.30336 | CF46: 2.30337 | CG46: 2.29997 | CH46: 2.30005 | CI46: 2.29422 | CJ46: 2.29096 | CK46: 2.29097 | CL46: 2.29098 | CM46: 2.29099 | CN46: 2.29776 | CO46: 2.28351 | CP46: 2.29545 | CR46: 2.27353 | CS46: 2.27354 | CT46: 2.27355 | CU46: 2.27356 | CV46: 2.26606 | CW46: 2.26607 | CX46: 2.26358 | CY46: 2.26359 | CZ46: 2.25609 | DA46: 2.2561
A47: 42072 | C47: 0.51898 | D47: 0.6079 | E47: 0.66734 | F47: 0.66082 | G47: 0.67487 | H47: 0.60098 | I47: 0.69806 | J47: 0.64494 | K47: 0.6557 | L47: 0.67323 | M47: 0.6096 | N47: 0.73976 | O47: 0.71032 | P47: 0.65756 | Q47: 0.67137 | R47: 0.74208 | S47: 0.77629 | T47: 0.74722 | U47: 0.7124 | V47: 0.78589 | W47: 0.82501 | X47: 0.95837 | Y47: 0.88949 | Z47: 0.96253 | AA47: 0.96158 | AB47: 1.05965 | AC47: 1.03704 | AD47: 0.96338 | AE47: 1.1064 | AF47: 1.1408 | AG47: 1.19759 | AH47: 1.19339 | AI47: 1.19921 | AJ47: 1.08062 | AK47: 1.27677 | AL47: 1.40193 | AM47: 1.21625 | AN47: 1.45697 | AO47: 1.55699 | AP47: 1.38358 | AQ47: 1.60103 | AR47: 1.64595 | AS47: 1.67769 | AT47: 1.67177 | AU47: 1.60991 | AV47: 2.08414 | AW47: 2.10167 | AX47: 2.12905 | AY47: 2.14178 | AZ47: 2.15841 | BA47: 2.21752 | BB47: 2.2564 | BC47: 2.29213 | BD47: 2.20375 | BE47: 2.35084 | BF47: 2.34585 | BG47: 2.34739 | BH47: 2.33488 | BI47: 2.33489 | BJ47: 2.3299 | BK47: 2.32492 | BL47: 2.31993 | BM47: 2.29995 | BN47: 2.281 | BO47: 2.29596 | BP47: 2.29597 | BQ47: 2.29098 | BR47: 2.29098 | BS47: 2.29099 | BV47: 2.30101 | BW47: 2.30101 | BX47: 2.29287 | BY47: 2.28956 | BZ47: 2.28956 | CA47: 2.28957 | CB47: 2.28958 | CC47: 2.28958 | CD47: 2.28626 | CE47: 2.28627 | CF47: 2.28627 | CG47: 2.28613 | CH47: 2.28633 | CI47: 2.28113 | CJ47: 2.27611 | CK47: 2.27612 | CL47: 2.27612 | CM47: 2.27964 | CN47: 2.27798 | CO47: 2.26864 | CP47: 2.27298 | CR47: 2.27361 | CS47: 2.26599 | CT47: 2.26599 | CU47: 2.266 | CV47: 2.26316 | CW47: 2.26316 | CX47: 2.26066 | CY47: 2.24869 | CZ47: 2.25318 | DA47: 2.25318 | DB47: 2.17139
A48: 42073 | C48: 0.46873 | D48: 0.59515 | E48: 0.67219 | F48: 0.62787 | G48: 0.65674 | H48: 0.60056 | I48: 0.68813 | J48: 0.6308 | K48: 0.64605 | L48: 0.65831 | M48: 0.59888 | N48: 0.72582 | O48: 0.69877 | P48: 0.65041 | Q48: 0.66864 | R48: 0.73414 | S48: 0.7696 | T48: 0.71665 | U48: 0.70479 | V48: 0.78013 | W48: 0.8191 | X48: 0.93983 | Y48: 0.86476 | Z48: 0.93631 | AA48: 0.93641 | AB48: 1.01572 | AC48: 1.00829 | AD48: 0.9339 | AE48: 1.08002 | AF48: 1.11239 | AG48: 1.1683 | AH48: 1.16625 | AI48: 1.17267 | AJ48: 1.05488 | AK48: 1.24736 | AL48: 1.36991 | AM48: 1.18706 | AN48: 1.42517 | AO48: 1.52092 | AP48: 1.34901 | AQ48: 1.56496 | AR48: 1.60789 | AS48: 1.64041 | AT48: 1.63356 | AU48: 1.56638 | AV48: 2.04682 | AW48: 2.06486 | AX48: 2.08989 | AY48: 2.09828 | AZ48: 2.11997 | BA48: 2.17957 | BB48: 2.21651 | BC48: 2.25851 | BD48: 2.16405 | BE48: 2.31134 | BF48: 2.30635 | BG48: 2.30772 | BH48: 2.29538 | BI48: 2.29539 | BJ48: 2.2904 | BK48: 2.28542 | BL48: 2.28042 | BM48: 2.26139 | BN48: 2.2421 | BO48: 2.2574 | BP48: 2.25741 | BQ48: 2.25242 | BR48: 2.25243 | BS48: 2.25244 | BV48: 2.25715 | BW48: 2.26151 | BX48: 2.25383 | BY48: 2.25051 | BZ48: 2.25052 | CA48: 2.25053 | CB48: 2.25053 | CC48: 2.25054 | CD48: 2.24722 | CE48: 2.24722 | CF48: 2.24723 | CG48: 2.2466 | CH48: 2.24728 | CI48: 2.24395 | CJ48: 2.23755 | CK48: 2.23756 | CL48: 2.23756 | CM48: 2.23757 | CN48: 2.23507 | CO48: 2.23008 | CP48: 2.23393 | CR48: 2.23411 | CS48: 2.23286 | CT48: 2.23287 | CU48: 2.23287 | CV48: 2.22565 | CW48: 2.22565 | CX48: 2.22314 | CY48: 2.21013 | CZ48: 2.21566 | DA48: 2.21567 | DB48: 2.13234
A49: 42074 | C49: 0.45453 | D49: 0.5699 | E49: 0.6642 | F49: 0.67159 | G49: 0.65779 | H49: 0.59787 | I49: 0.67432 | J49: 0.62563 | K49: 0.63768 | L49: 0.64989 | M49: 0.59491 | N49: 0.73541 | O49: 0.69168 | P49: 0.64586 | Q49: 0.65885 | R49: 0.73044 | S49: 0.76656 | T49: 0.70942 | U49: 0.69724 | V49: 0.77282 | W49: 0.8103 | X49: 0.88983 | Y49: 0.8348 | Z49: 0.90777 | AA49: 0.90722 | AB49: 0.98281 | AC49: 0.97353 | AD49: 0.90036 | AE49: 1.04431 | AF49: 1.07061 | AG49: 1.13422 | AH49: 1.13026 | AI49: 1.1365 | AJ49: 1.01781 | AK49: 1.21284 | AL49: 1.33367 | AM49: 1.15476 | AN49: 1.38282 | AO49: 1.47291 | AP49: 1.30185 | AQ49: 1.51699 | AR49: 1.56143 | AS49: 1.59317 | AT49: 1.58649 | AU49: 1.52122 | AV49: 2.00592 | AW49: 2.02368 | AX49: 2.05005 | AY49: 2.05629 | AZ49: 2.07798 | BA49: 2.13927 | BB49: 2.17472 | BC49: 2.21272 | BD49: 2.12224 | BE49: 2.27005 | BF49: 2.26866 | BG49: 2.26873 | BH49: 2.25471 | BI49: 2.25702 | BJ49: 2.25204 | BK49: 2.24707 | BL49: 2.24208 | BM49: 2.22211 | BN49: 2.20249 | BO49: 2.22482 | BP49: 2.22483 | BQ49: 2.21316 | BR49: 2.21317 | BS49: 2.21319 | BV49: 2.22321 | BW49: 2.22322 | BX49: 2.21493 | BY49: 2.21162 | BZ49: 2.21163 | CA49: 2.21165 | CB49: 2.21166 | CC49: 2.21167 | CD49: 2.20835 | CE49: 2.20836 | CF49: 2.20837 | CG49: 2.20838 | CH49: 2.20784 | CI49: 2.20111 | CJ49: 2.19837 | CK49: 2.19838 | CL49: 2.19839 | CM49: 2.20177 | CN49: 2.19591 | CO49: 2.19092 | CP49: 2.19511 | CR49: 2.1959 | CS49: 2.19883 | CT49: 2.19884 | CU49: 2.19885 | CV49: 2.18652 | CW49: 2.18653 | CX49: 2.18402 | CY49: 2.17099 | CZ49: 2.17655 | DA49: 2.17655 | DB49: 2.09356
A50: 42075 | C50: 0.07953 | D50: 0.55106 | E50: 0.63981 | F50: 0.65825 | G50: 0.64426 | H50: 0.58602 | I50: 0.66444 | J50: 0.60852 | K50: 0.62215 | L50: 0.63799 | M50: 0.5825 | N50: 0.71786 | O50: 0.67693 | P50: 0.63749 | Q50: 0.65476 | R50: 0.71962 | S50: 0.77 | T50: 0.69671 | U50: 0.68521 | V50: 0.7626 | W50: 0.80095 | X50: 0.88035 | Y50: 0.82606 | Z50: 0.89949 | AA50: 0.89821 | AB50: 0.97996 | AC50: 0.94265 | AD50: 0.88639 | AE50: 1.03223 | AF50: 1.06192 | AG50: 1.12062 | AH50: 1.10039 | AI50: 1.12332 | AJ50: 1.00423 | AK50: 1.19927 | AL50: 1.32524 | AM50: 1.14808 | AN50: 1.37409 | AO50: 1.46739 | AP50: 1.30369 | AQ50: 1.51146 | AR50: 1.5548 | AS50: 1.58719 | AT50: 1.58331 | AU50: 1.51566 | AV50: 1.99794 | AW50: 2.01445 | AX50: 2.04183 | AY50: 2.05082 | AZ50: 2.07588 | BA50: 2.13008 | BB50: 2.1669 | BC50: 2.21016 | BD50: 2.10465 | BE50: 2.26102 | BF50: 2.25771 | BG50: 2.25807 | BH50: 2.24442 | BI50: 2.24781 | BJ50: 2.24283 | BK50: 2.23785 | BL50: 2.23749 | BM50: 2.2129 | BN50: 2.19035 | BO50: 2.21553 | BP50: 2.21555 | BQ50: 2.20394 | BR50: 2.20396 | BS50: 2.20397 | BV50: 2.214 | BW50: 2.21401 | BX50: 2.20565 | BY50: 2.20234 | BZ50: 2.20235 | CA50: 2.20236 | CB50: 2.20237 | CC50: 2.20238 | CD50: 2.19906 | CE50: 2.19907 | CF50: 2.19909 | CG50: 2.19909 | CH50: 2.19837 | CI50: 2.19178 | CJ50: 2.18916 | CK50: 2.18917 | CL50: 2.18918 | CM50: 2.18919 | CN50: 2.18669 | CO50: 2.1817 | CP50: 2.18582 | CR50: 2.18669 | CS50: 2.1905 | CT50: 2.19051 | CU50: 2.19051 | CV50: 2.17874 | CW50: 2.17874 | CX50: 2.17624 | CY50: 2.17127 | CZ50: 2.16876 | DA50: 2.16877 | DB50: 2.08081
A51: 42076 | C51: 0.1218 | D51: 0.53617 | E51: 0.62513 | F51: 0.64907 | G51: 0.63591 | H51: 0.56854 | I51: 0.66441 | J51: 0.59329 | K51: 0.60311 | L51: 0.62609 | M51: 0.56618 | N51: 0.68857 | O51: 0.66451 | P51: 0.60943 | Q51: 0.63409 | R51: 0.69844 | S51: 0.73458 | T51: 0.67659 | U51: 0.66763 | V51: 0.74238 | W51: 0.79588 | X51: 0.86149 | Y51: 0.80976 | Z51: 0.8792 | AA51: 0.87721 | AB51: 0.96379 | AC51: 0.92228 | AD51: 0.87035 | AE51: 1.01894 | AF51: 1.05935 | AG51: 1.11369 | AH51: 1.09393 | AI51: 1.12284 | AJ51: 0.98938 | AK51: 1.19311 | AL51: 1.31995 | AM51: 1.13705 | AN51: 1.3673 | AO51: 1.46439 | AP51: 1.29136 | AQ51: 1.51345 | AR51: 1.55277 | AS51: 1.58043 | AT51: 1.57385 | AU51: 1.50268 | AV51: 1.99305 | AW51: 1.9789 | AX51: 2.03731 | AY51: 2.04715 | AZ51: 2.06844 | BA51: 2.12181 | BB51: 2.15216 | BC51: 2.19578 | BD51: 2.10389 | BE51: 2.25204 | BF51: 2.24873 | BG51: 2.24684 | BH51: 2.23545 | BI51: 2.23668 | BJ51: 2.2317 | BK51: 2.22672 | BL51: 2.22173 | BM51: 2.20456 | BN51: 2.18123 | BO51: 2.20655 | BP51: 2.20657 | BQ51: 2.19611 | BR51: 2.19613 | BS51: 2.19614 | BV51: 2.19998 | BW51: 2.20338 | BX51: 2.19667 | BY51: 2.19336 | BZ51: 2.19337 | CA51: 2.19338 | CB51: 2.1955 | CC51: 2.19551 | CD51: 2.19008 | CE51: 2.19009 | CF51: 2.1901 | CG51: 2.18787 | CH51: 2.18719 | CI51: 2.18593 | CJ51: 2.18132 | CK51: 2.18133 | CL51: 2.18134 | CM51: 2.18135 | CN51: 2.18561 | CO51: 2.17387 | CP51: 2.17685 | CR51: 2.16389 | CS51: 2.17581 | CT51: 2.17582 | CU51: 2.17582 | CV51: 2.16853 | CW51: 2.16854 | CX51: 2.15394 | CY51: 2.15394 | CZ51: 2.15856 | DA51: 2.15857 | DB51: 2.06605
A52: 42079 | D52: 0.54495 | E52: 0.61283 | F52: 0.60441 | G52: 0.6121 | H52: 0.54608 | I52: 0.62854 | J52: 0.57383 | K52: 0.58651 | L52: 0.60556 | M52: 0.55008 | N52: 0.66917 | O52: 0.64622 | P52: 0.60609 | Q52: 0.61345 | R52: 0.68897 | S52: 0.72472 | T52: 0.66377 | U52: 0.65332 | V52: 0.72734 | W52: 0.78263 | X52: 0.83667 | Y52: 0.78545 | Z52: 0.85369 | AA52: 0.85312 | AB52: 0.93049 | AC52: 0.8999 | AD52: 0.84414 | AE52: 0.99599 | AF52: 1.03659 | AG52: 1.09056 | AH52: 1.06827 | AI52: 1.09969 | AJ52: 0.97473 | AK52: 1.17009 | AL52: 1.2949 | AM52: 1.09784 | AN52: 1.33906 | AO52: 1.43243 | AP52: 1.25844 | AQ52: 1.48664 | AR52: 1.52032 | AS52: 1.54779 | AT52: 1.51527 | AU52: 1.47024 | AV52: 1.95078 | AW52: 1.96704 | AX52: 1.99804 | AY52: 2.00857 | AZ52: 2.02983 | BA52: 2.0938 | BB52: 2.11795 | BC52: 2.16163 | BD52: 2.07509 | BE52: 2.21866 | BF52: 2.21534 | BG52: 2.21571 | BH52: 2.20203 | BI52: 2.20537 | BJ52: 2.20038 | BK52: 2.1954 | BL52: 2.19041 | BM52: 2.17042 | BN52: 2.14671 | BO52: 2.16644 | BP52: 2.16644 | BQ52: 2.17644 | BR52: 2.17645 | BS52: 2.17646 | BV52: 2.17148 | BW52: 2.17149 | BX52: 2.16249 | BY52: 2.15918 | BZ52: 2.15919 | CA52: 2.15919 | CB52: 2.1592 | CC52: 2.15921 | CD52: 2.15588 | CE52: 2.15589 | CF52: 2.15589 | CG52: 2.15493 | CH52: 2.15494 | CI52: 2.15293 | CJ52: 2.14658 | CK52: 2.14658 | CL52: 2.14659 | CM52: 2.14659 | CN52: 2.1441 | CO52: 2.1491 | CP52: 2.13661 | CR52: 2.14409 | CS52: 2.15567 | CT52: 2.15567 | CU52: 2.15568 | CV52: 2.13765 | CW52: 2.13766 | CX52: 2.13515 | CY52: 2.13017 | CZ52: 2.12767 | DA52: 2.12767 | DB52: 2.03436
A53: 42080 | D53: 0.54842 | E53: 0.61277 | F53: 0.58892 | G53: 0.61338 | H53: 0.55135 | I53: 0.62852 | J53: 0.58791 | K53: 0.58914 | L53: 0.61252 | M53: 0.55468 | N53: 0.67032 | O53: 0.6655 | P53: 0.60166 | Q53: 0.6265 | R53: 0.6918 | S53: 0.72838 | T53: 0.66988 | U53: 0.66014 | V53: 0.73487 | W53: 0.78865 | X53: 0.8228 | Y53: 0.77182 | Z53: 0.84078 | AA53: 0.84008 | AB53: 0.91537 | AC53: 0.88537 | AD53: 0.8298 | AE53: 0.97905 | AF53: 1.0209 | AG53: 1.08922 | AH53: 1.08698 | AI53: 1.08345 | AJ53: 0.95707 | AK53: 1.15414 | AL53: 1.26032 | AM53: 1.08671 | AN53: 1.30591 | AO53: 1.39438 | AP53: 1.2268 | AQ53: 1.44919 | AR53: 1.48948 | AS53: 1.51688 | AT53: 1.5089 | AU53: 1.43612 | AV53: 1.91833 | AW53: 1.93479 | AX53: 1.96522 | AY53: 1.97589 | AZ53: 1.99715 | BA53: 2.06215 | BB53: 2.08774 | BC53: 2.13191 | BD53: 2.03389 | BE53: 2.18709 | BF53: 2.18377 | BG53: 2.18217 | BH53: 2.17013 | BI53: 2.1732 | BJ53: 2.16821 | BK53: 2.16322 | BL53: 2.16156 | BM53: 2.15323 | BN53: 2.11353 | BO53: 2.14019 | BP53: 2.1402 | BQ53: 2.14376 | BR53: 2.12878 | BS53: 2.12879 | BV53: 2.13881 | BW53: 2.13881 | BX53: 2.13025 | BY53: 2.12694 | BZ53: 2.12695 | CA53: 2.12695 | CB53: 2.12696 | CC53: 2.12697 | CD53: 2.12364 | CE53: 2.12365 | CF53: 2.12366 | CG53: 2.12366 | CH53: 2.12161 | CI53: 2.1154 | CJ53: 2.1139 | CK53: 2.11391 | CL53: 2.11391 | CM53: 2.11702 | CN53: 2.11142 | CO53: 2.10643 | CP53: 2.11036 | CR53: 2.11141 | CS53: 2.11409 | CT53: 2.11409 | CU53: 2.11409 | CV53: 2.10203 | CW53: 2.10203 | CX53: 2.09953 | CY53: 2.09455 | CZ53: 2.09205 | DA53: 2.09205 | DB53: 1.99715
A54: 42081 | D54: 0.52384 | E54: 0.60517 | F54: 0.62749 | G54: 0.6005 | H54: 0.52234 | I54: 0.62484 | J54: 0.58493 | K54: 0.55088 | L54: 0.56066 | M54: 0.50159 | N54: 0.65196 | O54: 0.64384 | P54: 0.54782 | Q54: 0.56735 | R54: 0.6426 | S54: 0.68033 | T54: 0.62121 | U54: 0.61113 | V54: 0.68315 | W54: 0.73862 | X54: 0.74305 | Y54: 0.69507 | Z54: 0.76265 | AA54: 0.7565 | AB54: 0.83366 | AC54: 0.82103 | AD54: 0.74667 | AE54: 0.89796 | AF54: 0.93908 | AG54: 1.00664 | AH54: 0.97389 | AI54: 1.00133 | AJ54: 0.86489 | AK54: 1.07154 | AL54: 1.16609 | AM54: 0.97711 | AN54: 1.21537 | AO54: 1.30014 | AP54: 1.13287 | AQ54: 1.35597 | AR54: 1.39766 | AS54: 1.42515 | AT54: 1.41765 | AU54: 1.34851 | AV54: 1.83062 | AW54: 1.84551 | AX54: 1.87802 | AY54: 1.88829 | AZ54: 1.91381 | BA54: 1.98215 | BB54: 2.0125 | BC54: 2.05636 | BD54: 1.96776 | BE54: 2.11356 | BF54: 2.11025 | BG54: 2.11054 | BH54: 2.09663 | BI54: 2.09998 | BJ54: 2.095 | BK54: 2.09002 | BL54: 2.08896 | BM54: 2.06506 | BN54: 2.04002 | BO54: 2.06607 | BP54: 2.06608 | BQ54: 2.0551 | BR54: 2.07011 | BS54: 2.07012 | BV54: 2.06516 | BW54: 2.06517 | BX54: 2.05617 | BY54: 2.05286 | BZ54: 2.05287 | CA54: 2.05288 | CB54: 2.05523 | CC54: 2.05524 | CD54: 2.04958 | CE54: 2.04959 | CF54: 2.0496 | CG54: 2.04788 | CH54: 2.04788 | CI54: 2.0459 | CJ54: 2.04031 | CK54: 2.04032 | CL54: 2.04033 | CM54: 2.04033 | CN54: 2.03784 | CO54: 2.03285 | CP54: 2.03634 | CR54: 2.03785 | CS54: 2.04827 | CT54: 2.04828 | CU54: 2.04828 | CV54: 2.03028 | CW54: 2.03029 | CX54: 2.02779 | CY54: 2.02281 | CZ54: 2.02031 | DA54: 2.02032 | DB54: 1.92785
A55: 42082 | D55: 0.5101 | E55: 0.58566 | F55: 0.59347 | G55: 0.58975 | H55: 0.51776 | I55: 0.60511 | J55: 0.57528 | K55: 0.54056 | L55: 0.55173 | M55: 0.49471 | N55: 0.63888 | O55: 0.61179 | P55: 0.54875 | Q55: 0.56764 | R55: 0.63379 | S55: 0.6709 | T55: 0.61214 | U55: 0.60233 | V55: 0.67539 | W55: 0.73006 | X55: 0.74566 | Y55: 0.69538 | Z55: 0.76401 | AA55: 0.76303 | AB55: 0.83462 | AC55: 0.81459 | AD55: 0.74674 | AE55: 0.89732 | AF55: 0.93644 | AG55: 1.00312 | AH55: 0.97071 | AI55: 0.998 | AJ55: 0.86408 | AK55: 1.06752 | AL55: 1.16018 | AM55: 0.98315 | AN55: 1.208 | AO55: 1.29075 | AP55: 1.1252 | AQ55: 1.34577 | AR55: 1.38927 | AS55: 1.41622 | AT55: 1.4104 | AU55: 1.33981 | AV55: 1.81843 | AW55: 1.83132 | AX55: 1.86553 | AY55: 1.8766 | AZ55: 1.89788 | BA55: 1.95479 | BB55: 1.99208 | BC55: 2.03749 | BD55: 1.93869 | BE55: 2.09178 | BF55: 2.09118 | BG55: 2.0912 | BH55: 2.07756 | BI55: 2.07998 | BJ55: 2.075 | BK55: 2.07002 | BL55: 2.06896 | BM55: 2.06004 | BN55: 2.01796 | BO55: 2.04732 | BP55: 2.04734 | BQ55: 2.036 | BR55: 2.03602 | BS55: 2.03603 | BV55: 2.04515 | BW55: 2.04517 | BX55: 2.03743 | BY55: 2.03412 | BZ55: 2.03413 | CA55: 2.03414 | CB55: 2.03415 | CC55: 2.03416 | CD55: 2.03084 | CE55: 2.03085 | CF55: 2.03086 | CG55: 2.03028 | CH55: 2.0298 | CI55: 2.02457 | CJ55: 2.0212 | CK55: 2.02121 | CL55: 2.02122 | CM55: 2.02425 | CN55: 2.01873 | CO55: 2.01374 | CP55: 2.0176 | CR55: 2.00377 | CS55: 2.01121 | CT55: 2.01121 | CU55: 2.01122 | CV55: 2.00828 | CW55: 2.00828 | CX55: 2.00578 | CY55: 1.99381 | CZ55: 1.9983 | DA55: 1.99831 | DB55: 1.90371
A56: 42083 | D56: 0.50117 | E56: 0.55646 | F56: 0.59047 | G56: 0.57676 | H56: 0.49425 | I56: 0.57551 | J56: 0.57721 | K56: 0.52316 | L56: 0.54875 | M56: 0.48187 | N56: 0.60594 | O56: 0.60606 | P56: 0.51096 | Q56: 0.54506 | R56: 0.60906 | S56: 0.64749 | T56: 0.57983 | U56: 0.58547 | V56: 0.65993 | W56: 0.71332 | X56: 0.72976 | Y56: 0.67958 | Z56: 0.74869 | AA56: 0.74758 | AB56: 0.8179 | AC56: 0.78301 | AD56: 0.73071 | AE56: 0.87899 | AF56: 0.91823 | AG56: 0.98426 | AH56: 0.95399 | AI56: 0.98034 | AJ56: 0.85347 | AK56: 1.0502 | AL56: 1.14274 | AM56: 0.96506 | AN56: 1.19263 | AO56: 1.2797 | AP56: 1.11246 | AQ56: 1.32874 | AR56: 1.37308 | AS56: 1.39979 | AT56: 1.39279 | AU56: 1.3241 | AV56: 1.80283 | AW56: 1.81305 | AX56: 1.84928 | AY56: 1.86752 | AZ56: 1.88782 | BA56: 1.95136 | BB56: 1.9787 | BC56: 2.01969 | BD56: 1.92074 | BE56: 2.08264 | BF56: 2.07934 | BG56: 2.07478 | BH56: 2.07028 | BI56: 2.07254 | BJ56: 2.06923 | BK56: 2.06258 | BL56: 2.05594 | BM56: 2.05037 | BN56: 2.00283 | BO56: 2.04039 | BP56: 2.04041 | BQ56: 2.04042 | BR56: 2.04043 | BS56: 2.04045 | BV56: 2.03548 | BW56: 2.03607 | BX56: 2.03274 | BY56: 2.02552 | BZ56: 2.01896 | CA56: 2.01897 | CB56: 2.02105 | CC56: 2.02106 | CD56: 2.01567 | CE56: 2.01568 | CF56: 2.01569 | CG56: 2.0157 | CH56: 2.01305 | CI56: 2.0062 | CJ56: 2.00563 | CK56: 2.00564 | CL56: 2.00564 | CM56: 2.00908 | CN56: 2.01095 | CO56: 2.00408 | CP56: 2.00591 | CR56: 2.00215 | CS56: 1.99426 | CT56: 1.99426 | CU56: 1.98821 | CV56: 1.99093 | CW56: 1.99093 | CX56: 1.98843 | CY56: 1.97824 | CZ56: 1.98095 | DA56: 1.98096 | DB56: 1.88567
A57: 42086 | D57: 0.53042 | E57: 0.56426 | F57: 0.59431 | G57: 0.57834 | H57: 0.4967 | I57: 0.57985 | J57: 0.58092 | K57: 0.52429 | L57: 0.54884 | M57: 0.48244 | N57: 0.60879 | O57: 0.58934 | P57: 0.51 | Q57: 0.53599 | R57: 0.60909 | S57: 0.64696 | T57: 0.5797 | U57: 0.58475 | V57: 0.64739 | W57: 0.71114 | X57: 0.72934 | Y57: 0.67912 | Z57: 0.74815 | AA57: 0.74752 | AB57: 0.81735 | AC57: 0.7838 | AD57: 0.73055 | AE57: 0.8784 | AF57: 0.9182 | AG57: 0.98517 | AH57: 0.95521 | AI57: 0.98082 | AJ57: 0.84409 | AK57: 1.05185 | AL57: 1.14707 | AM57: 0.97387 | AN57: 1.19592 | AO57: 1.28188 | AP57: 1.11406 | AQ57: 1.3309 | AR57: 1.37553 | AS57: 1.40192 | AT57: 1.39566 | AU57: 1.32469 | AV57: 1.8085 | AW57: 1.79235 | AX57: 1.85246 | AY57: 1.86859 | AZ57: 1.88996 | BA57: 1.95349 | BB57: 1.98441 | BC57: 2.02498 | BD57: 1.92988 | BE57: 2.0913 | BF57: 2.08799 | BG57: 2.08303 | BH57: 2.07861 | BI57: 2.0805 | BJ57: 2.07718 | BK57: 2.07052 | BL57: 2.06387 | BM57: 2.05866 | BN57: 2.00975 | BO57: 2.04867 | BP57: 2.04868 | BQ57: 2.04869 | BR57: 2.04869 | BS57: 2.0487 | BV57: 2.04372 | BW57: 2.04395 | BX57: 2.04062 | BY57: 2.03375 | BZ57: 2.02749 | CA57: 2.0275 | CB57: 2.03146 | CC57: 2.03147 | CD57: 2.02481 | CE57: 2.02482 | CF57: 2.02482 | CG57: 2.02149 | CH57: 2.0215 | CI57: 2.01475 | CJ57: 2.02003 | CK57: 2.02004 | CL57: 2.02004 | CM57: 2.02004 | CN57: 2.02005 | CO57: 2.01504 | CP57: 2.02628 | CR57: 2.01002 | CS57: 2.00626 | CT57: 2.00627 | CU57: 2.00627 | CV57: 1.99628 | CW57: 1.99628 | CX57: 1.99628 | CY57: 1.99131 | CZ57: 1.99249 | DA57: 1.9925 | DB57: 1.89511
A58: 42087 | D58: 0.5271 | E58: 0.56812 | F58: 0.59585 | G58: 0.56883 | H58: 0.50711 | I58: 0.57984 | J58: 0.58301 | K58: 0.53444 | L58: 0.54585 | M58: 0.48702 | N58: 0.62475 | O58: 0.61145 | P58: 0.52757 | Q58: 0.55462 | R58: 0.62049 | S58: 0.6591 | T58: 0.59066 | U58: 0.59587 | V58: 0.6695 | W58: 0.72308 | X58: 0.73127 | Y58: 0.68248 | Z58: 0.75051 | AA58: 0.74962 | AB58: 0.81931 | AC58: 0.78475 | AD58: 0.73096 | AE58: 0.88077 | AF58: 0.91973 | AG58: 0.9867 | AH58: 0.98124 | AI58: 0.98439 | AJ58: 0.84481 | AK58: 1.05375 | AL58: 1.14571 | AM58: 0.96788 | AN58: 1.19557 | AO58: 1.26806 | AP58: 1.10293 | AQ58: 1.32338 | AR58: 1.36814 | AS58: 1.39475 | AT58: 1.38941 | AU58: 1.32017 | AV58: 1.79834 | AW58: 1.81075 | AX58: 1.84597 | AY58: 1.86574 | AZ58: 1.87847 | BA58: 1.94197 | BB58: 1.97508 | BC58: 2.02312 | BD58: 1.92277 | BE58: 2.0794 | BF58: 2.07609 | BG58: 2.07336 | BH58: 2.06643 | BI58: 2.06971 | BJ58: 2.06146 | BK58: 2.05974 | BL58: 2.05309 | BM58: 2.04649 | BN58: 1.99672 | BO58: 2.0365 | BP58: 2.03651 | BQ58: 2.03652 | BR58: 2.03652 | BS58: 2.03653 | BV58: 2.03155 | BW58: 2.03317 | BX58: 2.02656 | BY58: 2.02157 | BZ58: 2.01459 | CA58: 2.0146 | CB58: 2.01461 | CC58: 2.01461 | CD58: 2.01129 | CE58: 2.01129 | CF58: 2.01066 | CG58: 2.00926 | CH58: 2.00927 | CI58: 2.00357 | CJ58: 1.99664 | CK58: 2.00569 | CL58: 2.00569 | CM58: 1.99665 | CN58: 2.0057 | CO58: 1.98917 | CP58: 2.00069 | CR58: 1.99567 | CS58: 2.01011 | CT58: 2.01012 | CU58: 2.01012 | CV58: 1.98604 | CW58: 1.98605 | CX58: 1.98709 | CY58: 1.98012 | CZ58: 1.98082 | DA58: 1.98083 | DB58: 1.88861
A59: 42088 | D59: 0.52608 | E59: 0.56075 | F59: 0.60744 | G59: 0.597 | H59: 0.51767 | I59: 0.57637 | J59: 0.58721 | K59: 0.55782 | L59: 0.57841 | M59: 0.51811 | N59: 0.63046 | O59: 0.63141 | P59: 0.55501 | Q59: 0.58212 | R59: 0.64619 | S59: 0.68599 | T59: 0.61459 | U59: 0.61962 | V59: 0.69384 | W59: 0.74661 | X59: 0.79612 | Y59: 0.71566 | Z59: 0.78607 | AA59: 0.78404 | AB59: 0.85957 | AC59: 0.82672 | AD59: 0.76331 | AE59: 0.90856 | AF59: 0.94811 | AG59: 1.01353 | AH59: 0.98295 | AI59: 1.01104 | AJ59: 0.88214 | AK59: 1.08067 | AL59: 1.16783 | AM59: 0.99461 | AN59: 1.22306 | AO59: 1.29948 | AP59: 1.1402 | AQ59: 1.34853 | AR59: 1.39583 | AS59: 1.42224 | AT59: 1.41683 | AU59: 1.34472 | AV59: 1.83279 | AW59: 1.81639 | AX59: 1.87723 | AY59: 1.89702 | AZ59: 1.92299 | BA59: 1.97773 | BB59: 2.02194 | BC59: 2.06284 | BD59: 1.97045 | BE59: 2.12044 | BF59: 2.11713 | BG59: 2.10989 | BH59: 2.10587 | BI59: 2.10799 | BJ59: 2.10468 | BK59: 2.09803 | BL59: 2.09139 | BM59: 2.08596 | BN59: 2.03679 | BO59: 2.07598 | BP59: 2.07599 | BQ59: 2.07601 | BR59: 2.07602 | BS59: 2.07603 | BV59: 2.07107 | BW59: 2.07152 | BX59: 2.06819 | BY59: 2.06111 | BZ59: 2.05509 | CA59: 2.0551 | CB59: 2.05951 | CC59: 2.05952 | CD59: 2.05287 | CE59: 2.05288 | CF59: 2.05289 | CG59: 2.04956 | CH59: 2.04957 | CI59: 2.04282 | CJ59: 2.04812 | CK59: 2.04813 | CL59: 2.04814 | CM59: 2.04815 | CN59: 2.04816 | CO59: 2.04315 | CP59: 2.05437 | CR59: 2.03814 | CS59: 2.03437 | CT59: 2.03438 | CU59: 2.03439 | CV59: 2.02439 | CW59: 2.0244 | CX59: 2.02441 | CY59: 2.01943 | CZ59: 2.02028 | DA59: 2.02029 | DB59: 1.92507
A60: 42089 | D60: 0.57038 | E60: 0.61875 | F60: 0.63505 | G60: 0.63514 | H60: 0.58463 | I60: 0.64434 | J60: 0.64487 | K60: 0.63443 | L60: 0.65566 | M60: 0.60185 | N60: 0.70506 | O60: 0.7013 | P60: 0.6469 | Q60: 0.67055 | R60: 0.73828 | S60: 0.80096 | T60: 0.70062 | U60: 0.70497 | V60: 0.78282 | W60: 0.81514 | X60: 0.87549 | Y60: 0.82497 | Z60: 0.89518 | AA60: 0.89395 | AB60: 0.97128 | AC60: 0.94191 | AD60: 0.87249 | AE60: 1.02218 | AF60: 1.05727 | AG60: 1.12676 | AH60: 1.09372 | AI60: 1.11545 | AJ60: 0.98499 | AK60: 1.18898 | AL60: 1.27915 | AM60: 1.10814 | AN60: 1.33217 | AO60: 1.41028 | AP60: 1.24419 | AQ60: 1.45601 | AR60: 1.50345 | AS60: 1.53474 | AT60: 1.52322 | AU60: 1.45823 | AV60: 1.93446 | AW60: 1.91927 | AX60: 1.97541 | AY60: 1.9898 | AZ60: 2.01256 | BA60: 2.06978 | BB60: 2.0989 | BC60: 2.14497 | BD60: 2.04941 | BE60: 2.18956 | BF60: 2.18626 | BG60: 2.18238 | BH60: 2.1713 | BI60: 2.17826 | BJ60: 2.17004 | BK60: 2.1683 | BL60: 2.16166 | BM60: 2.1551 | BN60: 2.10498 | BO60: 2.14412 | BP60: 2.14413 | BQ60: 2.14414 | BR60: 2.14416 | BS60: 2.14417 | BV60: 2.1392 | BW60: 2.14113 | BX60: 2.13423 | BY60: 2.12924 | BZ60: 2.12289 | CA60: 2.1229 | CB60: 2.12291 | CC60: 2.12292 | CD60: 2.1196 | CE60: 2.11961 | CF60: 2.11931 | CG60: 2.1179 | CH60: 2.11791 | CI60: 2.11458 | CJ60: 2.11434 | CK60: 2.11435 | CL60: 2.11436 | CM60: 2.11437 | CN60: 2.11437 | CO60: 2.10937 | CP60: 2.10938 | CR60: 2.10437 | CS60: 2.11883 | CT60: 2.11884 | CU60: 2.11885 | CV60: 2.09705 | CW60: 2.09705 | CX60: 2.09474 | CY60: 2.08977 | CZ60: 2.08954 | DA60: 2.08954 | DB60: 2.00101
A61: 42090 | D61: 0.55513 | E61: 0.61862 | F61: 0.61915 | G61: 0.62939 | H61: 0.54147 | I61: 0.64431 | J61: 0.63505 | K61: 0.58729 | L61: 0.60018 | M61: 0.5439 | N61: 0.68101 | O61: 0.6401 | P61: 0.58172 | Q61: 0.61225 | R61: 0.67978 | S61: 0.71286 | T61: 0.64078 | U61: 0.64562 | V61: 0.72248 | W61: 0.76356 | X61: 0.80857 | Y61: 0.75616 | Z61: 0.8277 | AA61: 0.82527 | AB61: 0.90024 | AC61: 0.87353 | AD61: 0.79268 | AE61: 0.95105 | AF61: 0.98102 | AG61: 1.05583 | AH61: 1.02438 | AI61: 1.04511 | AJ61: 0.91545 | AK61: 1.11805 | AL61: 1.21444 | AM61: 1.04056 | AN61: 1.26791 | AO61: 1.33955 | AP61: 1.17506 | AQ61: 1.39088 | AR61: 1.43896 | AS61: 1.47036 | AT61: 1.47151 | AU61: 1.38878 | AV61: 1.86847 | AW61: 1.87825 | AX61: 1.91212 | AY61: 1.92654 | AZ61: 1.94931 | BA61: 2.01218 | BB61: 2.03624 | BC61: 2.08194 | BD61: 1.98823 | BE61: 2.13541 | BF61: 2.1321 | BG61: 2.1268 | BH61: 2.1211 | BI61: 2.12288 | BJ61: 2.11957 | BK61: 2.11292 | BL61: 2.10628 | BM61: 2.10119 | BN61: 2.04742 | BO61: 2.09521 | BP61: 2.09523 | BQ61: 2.09524 | BR61: 2.09525 | BS61: 2.09527 | BV61: 2.09239 | BW61: 2.08908 | BX61: 2.08576 | BY61: 2.08243 | BZ61: 2.07535 | CA61: 2.07536 | CB61: 2.07581 | CC61: 2.07582 | CD61: 2.06593 | CE61: 2.06594 | CF61: 2.06546 | CG61: 2.06547 | CH61: 2.06079 | CI61: 2.05588 | CJ61: 2.05545 | CK61: 2.05546 | CL61: 2.05547 | CM61: 2.05548 | CN61: 2.05298 | CO61: 2.04799 | CP61: 2.05219 | CR61: 2.05298 | CS61: 2.05626 | CT61: 2.05627 | CU61: 2.05627 | CV61: 2.04411 | CW61: 2.04412 | CX61: 2.04161 | CY61: 2.02806 | CZ61: 2.03414 | DA61: 2.03414 | DB61: 1.95224
A62: 42093 | D62: 0.57173 | E62: 0.61182 | F62: 0.62279 | G62: 0.61836 | H62: 0.53331 | I62: 0.62831 | J62: 0.62814 | K62: 0.58167 | L62: 0.59752 | M62: 0.544 | N62: 0.66094 | O62: 0.63459 | P62: 0.57454 | Q62: 0.59798 | R62: 0.66299 | S62: 0.72796 | T62: 0.62484 | U62: 0.62843 | V62: 0.70336 | W62: 0.7412 | X62: 0.8045 | Y62: 0.74973 | Z62: 0.8212 | AA62: 0.81942 | AB62: 0.9086 | AC62: 0.85597 | AD62: 0.7881 | AE62: 0.94648 | AF62: 0.98076 | AG62: 1.05116 | AH62: 1.04679 | AI62: 1.03882 | AJ62: 0.91962 | AK62: 1.11135 | AL62: 1.22126 | AM62: 1.04102 | AN62: 1.27119 | AO62: 1.35405 | AP62: 1.18728 | AQ62: 1.40032 | AR62: 1.44614 | AS62: 1.4778 | AT62: 1.47787 | AU62: 1.40197 | AV62: 1.87536 | AW62: 1.86356 | AX62: 1.91878 | AY62: 1.94043 | AZ62: 1.96159 | BA62: 2.01766 | BB62: 2.03975 | BC62: 2.08417 | BD62: 1.98362 | BE62: 2.13887 | BF62: 2.13556 | BG62: 2.12713 | BH62: 2.12428 | BI62: 2.12521 | BJ62: 2.12189 | BK62: 2.11523 | BL62: 2.10858 | BM62: 2.10858 | BN62: 2.04701 | BO62: 2.10126 | BP62: 2.10127 | BQ62: 2.09837 | BR62: 2.09838 | BS62: 2.09838 | BV62: 2.09464 | BW62: 2.09131 | BX62: 2.08799 | BY62: 2.08466 | BZ62: 2.07843 | CA62: 2.07844 | CB62: 2.07801 | CC62: 2.07802 | CD62: 2.06863 | CE62: 2.06864 | CF62: 2.06878 | CG62: 2.06878 | CH62: 2.06338 | CI62: 2.05805 | CJ62: 2.0585 | CK62: 2.0585 | CL62: 2.05851 | CM62: 2.06214 | CN62: 2.06442 | CO62: 2.05102 | CP62: 2.05989 | CR62: 2.04103 | CS62: 2.0484 | CT62: 2.04841 | CU62: 2.04841 | CV62: 2.04541 | CW62: 2.04542 | CX62: 2.04291 | CY62: 2.03106 | CZ62: 2.03543 | DA62: 2.03543 | DB62: 1.94013
A63: 42094 | D63: 0.551 | E63: 0.59949 | F63: 0.63228 | G63: 0.62241 | H63: 0.53754 | I63: 0.62259 | J63: 0.62987 | K63: 0.577 | L63: 0.59205 | M63: 0.53227 | N63: 0.67798 | O63: 0.63699 | P63: 0.56244 | Q63: 0.59436 | R63: 0.66413 | S63: 0.69717 | T63: 0.60825 | U63: 0.61163 | V63: 0.67481 | W63: 0.729 | X63: 0.78252 | Y63: 0.72971 | Z63: 0.80172 | AA63: 0.79826 | AB63: 0.88129 | AC63: 0.84448 | AD63: 0.78521 | AE63: 0.93506 | AF63: 0.96704 | AG63: 1.04278 | AH63: 1.03856 | AI63: 1.02947 | AJ63: 0.90035 | AK63: 1.10291 | AL63: 1.21415 | AM63: 1.03531 | AN63: 1.26504 | AO63: 1.3453 | AP63: 1.17411 | AQ63: 1.39104 | AR63: 1.43813 | AS63: 1.47048 | AT63: 1.45829 | AU63: 1.38931 | AV63: 1.8731 | AW63: 1.88434 | AX63: 1.9167 | AY63: 1.93387 | AZ63: 1.9563 | BA63: 2.01153 | BB63: 2.03365 | BC63: 2.07271 | BD63: 1.97224 | BE63: 2.13238 | BF63: 2.12908 | BG63: 2.1238 | BH63: 2.11828 | BI63: 2.12015 | BJ63: 2.11684 | BK63: 2.1102 | BL63: 2.10356 | BM63: 2.0984 | BN63: 2.04295 | BO63: 2.09242 | BP63: 2.09244 | BQ63: 2.09246 | BR63: 2.09247 | BS63: 2.09249 | BV63: 2.0897 | BW63: 2.08638 | BX63: 2.08307 | BY63: 2.07974 | BZ63: 2.07259 | CA63: 2.0726 | CB63: 2.07312 | CC63: 2.07314 | CD63: 2.06351 | CE63: 2.06352 | CF63: 2.0632 | CG63: 2.06285 | CH63: 2.06022 | CI63: 2.05321 | CJ63: 2.05271 | CK63: 2.05272 | CL63: 2.05273 | CM63: 2.05274 | CN63: 2.05025 | CO63: 2.04526 | CP63: 2.04959 | CR63: 2.05024 | CS63: 2.04877 | CT63: 2.04878 | CU63: 2.04878 | CV63: 2.0418 | CW63: 2.0418 | CX63: 2.0393 | CY63: 2.02535 | CZ63: 2.03183 | DA63: 2.03184 | DB63: 1.9374
... A90: 42132 | D90: 0.55929 | E90: 0.68301 | F90: 0.7114 | G90: 0.74606 | H90: 0.75554 | I90: 0.71177 | J90: 0.77143 | K90: 0.75024 | L90: 0.76693 | M90: 0.69728 | N90: 0.83965 | O90: 0.80239 | P90: 0.72567 | Q90: 0.76403 | R90: 0.86277 | S90: 0.85933 | T90: 0.77446 | U90: 0.81099 | V90: 0.87682 | W90: 0.92164 | X90: 1.03444 | Y90: 0.97929 | Z90: 1.03248 | AA90: 1.03204 | AB90: 1.15592 | AC90: 1.13844 | AD90: 1.06336 | AE90: 1.20924 | AF90: 1.25847 | AG90: 1.32424 | AH90: 1.32064 | AI90: 1.33526 | AJ90: 1.21195 | AK90: 1.41399 | AL90: 1.5473 | AM90: 1.36855 | AN90: 1.60568 | AO90: 1.68523 | AP90: 1.51477 | AQ90: 1.73266 | AR90: 1.77116 | AS90: 1.81759 | AT90: 1.77128 | AU90: 1.71461 | AV90: 2.19109 | AW90: 2.20051 | AX90: 2.23024 | AY90: 2.24633 | AZ90: 2.27033 | BA90: 2.30875 | BB90: 2.32829 | BC90: 2.36739 | BD90: 2.27544 | BE90: 2.46186 | BF90: 2.44658 | BG90: 2.44051 | BH90: 2.43223 | BI90: 2.41874 | BJ90: 2.43247 | BK90: 2.4126 | BL90: 2.41271 | BM90: 2.41753 | BN90: 2.35111 | BO90: 2.39704 | BP90: 2.39706 | BQ90: 2.39707 | BR90: 2.39709 | BS90: 2.39211 | BV90: 2.38714 | BW90: 2.38887 | BX90: 2.38217 | BY90: 2.37458 | BZ90: 2.37459 | CA90: 2.3746 | CB90: 2.37893 | CC90: 2.37895 | CD90: 2.37091 | CE90: 2.37092 | CF90: 2.37101 | CG90: 2.36509 | CH90: 2.36234 | CI90: 2.36182 | CJ90: 2.36035 | CK90: 2.36036 | CL90: 2.36037 | CM90: 2.36038 | CN90: 2.35789 | CO90: 2.3529 | CP90: 2.35041 | CR90: 2.35487 | CS90: 2.35488 | CT90: 2.35489 | CU90: 2.35489 | CV90: 2.36454 | CW90: 2.36455 | CX90: 2.34989 | CY90: 2.34594 | CZ90: 2.34343 | DA90: 2.34344 | DB90: 2.25322
A91: 42135 | D91: 0.59801 | E91: 0.69491 | F91: 0.74694 | G91: 0.75588 | H91: 0.70134 | I91: 0.71659 | J91: 0.79166 | K91: 0.78441 | L91: 0.79398 | M91: 0.73215 | N91: 0.86964 | O91: 0.83396 | P91: 0.77002 | Q91: 0.80822 | R91: 0.9078 | S91: 0.91551 | T91: 0.82474 | U91: 0.86164 | V91: 0.92641 | W91: 0.97204 | X91: 1.11228 | Y91: 1.06179 | Z91: 1.11345 | AA91: 1.13129 | AB91: 1.24321 | AC91: 1.25788 | AD91: 1.14254 | AE91: 1.29821 | AF91: 1.35025 | AG91: 1.41978 | AH91: 1.41769 | AI91: 1.4328 | AJ91: 1.29612 | AK91: 1.51048 | AL91: 1.66822 | AM91: 1.49758 | AN91: 1.72147 | AO91: 1.80353 | AP91: 1.63632 | AQ91: 1.85701 | AR91: 1.89555 | AS91: 1.93559 | AT91: 1.88996 | AU91: 1.83635 | AV91: 2.30715 | AW91: 2.32244 | AX91: 2.3552 | AY91: 2.36854 | AZ91: 2.38546 | BA91: 2.42826 | BB91: 2.43509 | BC91: 2.47766 | BD91: 2.37699 | BE91: 2.56572 | BF91: 2.5596 | BG91: 2.55051 | BH91: 2.54476 | BI91: 2.53254 | BJ91: 2.53866 | BK91: 2.52257 | BL91: 2.51759 | BM91: 2.51821 | BN91: 2.45766 | BO91: 2.50722 | BP91: 2.50723 | BQ91: 2.50724 | BR91: 2.50725 | BS91: 2.50226 | BV91: 2.49728 | BW91: 2.49759 | BX91: 2.49426 | BY91: 2.48731 | BZ91: 2.48732 | CA91: 2.48733 | CB91: 2.48763 | CC91: 2.48764 | CD91: 2.47757 | CE91: 2.47758 | CF91: 2.47733 | CG91: 2.47733 | CH91: 2.47257 | CI91: 2.46768 | CJ91: 2.46739 | CK91: 2.4674 | CL91: 2.4674 | CM91: 2.46741 | CN91: 2.46491 | CO91: 2.45992 | CP91: 2.45743 | CR91: 2.44994 | CS91: 2.44994 | CT91: 2.44995 | CU91: 2.44995 | CV91: 2.44245 | CW91: 2.44246 | CX91: 2.43997 | CY91: 2.43997 | CZ91: 2.43247 | DA91: 2.43248
